Workbook

Sheet NSB antiguo
A1: Número | B1: Título | C1: Autor | D1: En el nuevo? | E1: En HTML?
A2: 1 | B2: A Belén se va y se viene | C2: Miguel Manzano | D2: =IF(ISNUMBER(MATCH(Tabla4[[#This Row],[Título]],CantoralDB[Título],0)),"OK","-") -> OK | E2: OK
A3: 2 | B3: Aclamad, justos, al Señor | C3: Francisco Palazón | D3: =IF(ISNUMBER(MATCH(Tabla4[[#This Row],[Título]],CantoralDB[Título],0)),"OK","-") -> OK | E3: -
A4: 3 | B4: Acuérdate de Jesucristo | C4: Deiss | D4: =IF(ISNUMBER(MATCH(Tabla4[[#This Row],[Título]],CantoralDB[Título],0)),"OK","-") -> OK | E4: -
A5: 4 | B5: A Dios den gracias los pueblos | C5: Juan Antonio Espinosa | D5: =IF(ISNUMBER(MATCH(Tabla4[[#This Row],[Título]],CantoralDB[Título],0)),"OK","-") -> OK | E5: OK
A6: 5 | B6: Abrid de par en par | C6: Perp. Socorro | D6: =IF(ISNUMBER(MATCH(Tabla4[[#This Row],[Título]],CantoralDB[Título],0)),"OK","-") -> OK | E6: -
A7: 6 | B7: Acompáñame, Señor, en la tribulación | C7: Francisco Palazón | D7: =IF(ISNUMBER(MATCH(Tabla4[[#This Row],[Título]],CantoralDB[Título],0)),"OK","-") -> OK | E7: -
A8: 7 | B8: Amáras al Señor tu Dios | C8: Perp. Socorro | D8: =IF(ISNUMBER(MATCH(Tabla4[[#This Row],[Título]],CantoralDB[Título],0)),"OK","-") -> - | E8: -
A9: 8 | B9: Abre tu tienda al Señor | C9: Carmelo Erdozáin | D9: =IF(ISNUMBER(MATCH(Tabla4[[#This Row],[Título]],CantoralDB[Título],0)),"OK","-") -> OK | E9: OK
A10: 9 | B10: Acerquémonos todos al altar | C10: Francisco Palazón | D10: =IF(ISNUMBER(MATCH(Tabla4[[#This Row],[Título]],CantoralDB[Título],0)),"OK","-") -> OK | E10: OK
A11: 10 | B11: Alegrémonos, hermanos | C11: José Pedro Martins | D11: =IF(ISNUMBER(MATCH(Tabla4[[#This Row],[Título]],CantoralDB[Título],0)),"OK","-") -> OK | E11: OK
A12: 11 | B12: Aclama al Señor, tierra entera | C12: Miguel Manzano | D12: =IF(ISNUMBER(MATCH(Tabla4[[#This Row],[Título]],CantoralDB[Título],0)),"OK","-") -> OK | E12: -
A13: 12 | B13: Al ver Jesús | C13: Joaquín Madurga | D13: =IF(ISNUMBER(MATCH(Tabla4[[#This Row],[Título]],CantoralDB[Título],0)),"OK","-") -> OK | E13: OK
... A54: 53 | B54: Cómo le cantaré al Señor | C54: Ricardo Cantalapiedra | D54: =IF(ISNUMBER(MATCH(Tabla4[[#This Row],[Título]],CantoralDB[Título],0)),"OK","-") -> OK | E54: -
A55: 53b | B55: Cielos, destilad el rocío | C55: Antonio Alcalde | D55: =IF(ISNUMBER(MATCH(Tabla4[[#This Row],[Título]],CantoralDB[Título],0)),"OK","-") -> OK | E55: -
A56: 54 | B56: Como lo había anunciado | C56: Capilla | D56: =IF(ISNUMBER(MATCH(Tabla4[[#This Row],[Título]],CantoralDB[Título],0)),"OK","-") -> OK | E56: -
A57: 55 | B57: Cristo fue sincero | C57: Carmelo Erdozáin | D57: =IF(ISNUMBER(MATCH(Tabla4[[#This Row],[Título]],CantoralDB[Título],0)),"OK","-") -> OK | E57: -
A58: 56 | B58: Como Jonás | C58: Al-Haraca | D58: =IF(ISNUMBER(MATCH(Tabla4[[#This Row],[Título]],CantoralDB[Título],0)),"OK","-") -> OK | E58: -
A59: 57 | B59: Cristo se entregó por nosotros | C59: Carmelo Erdozáin | D59: =IF(ISNUMBER(MATCH(Tabla4[[#This Row],[Título]],CantoralDB[Título],0)),"OK","-") -> OK | E59: -
A60: 58 | B60: Cristo es la imagen de Dios | C60: Carmelo Erdozáin | D60: =IF(ISNUMBER(MATCH(Tabla4[[#This Row],[Título]],CantoralDB[Título],0)),"OK","-") -> OK | E60: -
A61: 59 | B61: Cristo por nosotros | C61: Carmelo Erdozáin | D61: =IF(ISNUMBER(MATCH(Tabla4[[#This Row],[Título]],CantoralDB[Título],0)),"OK","-") -> OK | E61: OK
A62: 60 | B62: Con vosotros está | C62: Miguel Manzano | D62: =IF(ISNUMBER(MATCH(Tabla4[[#This Row],[Título]],CantoralDB[Título],0)),"OK","-") -> OK | E62: OK
A63: 61 | B63: Creo, Señor, firmemente | C63: Misa nicaragüense | D63: =IF(ISNUMBER(MATCH(Tabla4[[#This Row],[Título]],CantoralDB[Título],0)),"OK","-") -> OK | E63: -
A64: 62 | B64: Criaturas del Señor | C64: Francisco Palazón | D64: =IF(ISNUMBER(MATCH(Tabla4[[#This Row],[Título]],CantoralDB[Título],0)),"OK","-") -> OK | E64: -
A65: 63 | B65: Cristo nos da la libertad | C65: Carmelo Erdozáin | D65: =IF(ISNUMBER(MATCH(Tabla4[[#This Row],[Título]],CantoralDB[Título],0)),"OK","-") -> OK | E65: OK
A66: 64 | B66: Creo en Dios y en su Palabra | C66: Fdo Viejo | D66: =IF(ISNUMBER(MATCH(Tabla4[[#This Row],[Título]],CantoralDB[Título],0)),"OK","-") -> OK | E66: -
A67: 65 | B67: Cristo ha resucitado | C67: Taizé | D67: =IF(ISNUMBER(MATCH(Tabla4[[#This Row],[Título]],CantoralDB[Título],0)),"OK","-") -> OK | E67: OK
A68: 65b | B68: Comeremos de la mesa | C68: Juanjo Elezkano | D68: =IF(ISNUMBER(MATCH(Tabla4[[#This Row],[Título]],CantoralDB[Título],0)),"OK","-") -> OK | E68: OK
A69: 66 | B69: Cuándo vendrás, Señor | C69: Miguel Manzano | D69: =IF(ISNUMBER(MATCH(Tabla4[[#This Row],[Título]],CantoralDB[Título],0)),"OK","-") -> OK | E69: -
A70: 67 | B70: Cuando el pobre nada tiene | C70: Miguel Manzano | D70: =IF(ISNUMBER(MATCH(Tabla4[[#This Row],[Título]],CantoralDB[Título],0)),"OK","-") -> OK | E70: OK
A71: 68 | B71: Cuántos años han de pasar | C71: Carmelo Erdozáin | D71: =IF(ISNUMBER(MATCH(Tabla4[[#This Row],[Título]],CantoralDB[Título],0)),"OK","-") -> OK | E71: -
A72: 69 | B72: Cuando el pan que está en mi vida | C72: JEC | D72: =IF(ISNUMBER(MATCH(Tabla4[[#This Row],[Título]],CantoralDB[Título],0)),"OK","-") -> OK | E72: -
A73: 70 | B73: Cuando rezamos, cuando cantamos | C73: Cesáreo Gabarain | D73: =IF(ISNUMBER(MATCH(Tabla4[[#This Row],[Título]],CantoralDB[Título],0)),"OK","-") -> OK | E73: -
A74: 71 | B74: Dad gracias al Señor porque es bueno | C74: Francisco Palazón | D74: =IF(ISNUMBER(MATCH(Tabla4[[#This Row],[Título]],CantoralDB[Título],0)),"OK","-") -> OK | E74: -
A75: 72 | B75: Danos paz | C75: Popular | D75: =IF(ISNUMBER(MATCH(Tabla4[[#This Row],[Título]],CantoralDB[Título],0)),"OK","-") -> OK | E75: -
A76: 73 | B76: Dad gracias al Señor porque es bueno, porque su amor no tiene fin | C76: Juan Antonio Espinosa | D76: =IF(ISNUMBER(MATCH(Tabla4[[#This Row],[Título]],CantoralDB[Título],0)),"OK","-") -> - | E76: -
A77: 74 | B77: Dame, Señor, un corazón feliz | C77: Perp. Socorro | D77: =IF(ISNUMBER(MATCH(Tabla4[[#This Row],[Título]],CantoralDB[Título],0)),"OK","-") -> OK | E77: -
A78: 75 | B78: Danos un corazón | C78: Juan Antonio Espinosa | D78: =IF(ISNUMBER(MATCH(Tabla4[[#This Row],[Título]],CantoralDB[Título],0)),"OK","-") -> OK | E78: OK
A79: 76 | B79: Donde tú dices ley | C79: Ricardo Cantalapiedra | D79: =IF(ISNUMBER(MATCH(Tabla4[[#This Row],[Título]],CantoralDB[Título],0)),"OK","-") -> OK | E79: -
A80: 77 | B80: Dolorosa | C80: Juan Antonio Espinosa | D80: =IF(ISNUMBER(MATCH(Tabla4[[#This Row],[Título]],CantoralDB[Título],0)),"OK","-") -> OK | E80: OK
...

Sheet CantoralDB
A1: # | B1: Título | C1: Momento | D1: Número | E1: Número antiguo | F1: Número RCC | G1: Origen | H1: Tono | I1: Cejilla | J1: html | K1: Ag/Gr | L1: Columna1 | M1: Autor | N1: Álbum | O1: Nº | P1: Año | Q1: Carpeta | R1: Sección | S1: Ruta | T1: Referencia | U1: Linked | V1: link | W1: index.html | X1: check
A2: =ROW(CantoralDB[[#This Row],[Título]])-1 -> 1 | B2: Yo soy el que vive | H2: Re | J2: OK | M2: Ain Karem | N2: A todos los pueblos | O2: 1 | P2: 2010 | Q2: {=IF(OR(CantoralDB[[#This Row],[Autor]]="Taizé en español",CantoralDB[[#This Row],[Autor]]="Taizé original",CantoralDB[[#This Row],[Autor]]="Taizé"),"taize", IFERROR(_xlfn.XLOOKUP(CantoralDB[[#This Row],[Autor]],_xlfn.CHOOSECOLS(_xlfn.ANCHORARRAY(secciones!$A$3),1),_xlfn.CHOOSECOLS(_xlfn.ANCHORARRAY(secciones!$A$3),2)), IF(OR(CantoralDB[[#This Row],[Número antiguo]]<>"",CantoralDB[[#This Row],[Número]]<>""),"nsb","nuevas" )))} -> ain_karem | R2: {=IF(CantoralDB[[#This Row],[Autor]]="Taizé original","taize_orig", IF(CantoralDB[[#This Row],[Autor]]="Taizé en español","taize_esp", IF(CantoralDB[[#This Row],[Autor]]="Villancicos","villancicos", IF(OR(CantoralDB[[#This Row],[Número antiguo]]<>"",CantoralDB[[#This Row],[Número]]<>""),"nsb", IF(CantoralDB[[#This Row],[Número RCC]]<>"","rcce", IFERROR(_xlfn.XLOOKUP(CantoralDB[[#This Row],[Autor]],_xlfn.CHOOSECOLS(_xlfn.ANCHORARRAY(secciones!$A$3),1),_xlfn.CHOOSECOLS(_xlfn.ANCHORARRAY(secciones!$A$3),2)),"nuevas") )))))} -> ain_karem | S2: ="canciones/"&CantoralDB[[#This Row],[Carpeta]]&"/"&IF(CantoralDB[[#This Row],[Autor]]="Taizé en español", SUBSTITUTE(SUBSTITUTE(SUBSTITUTE(SUBSTITUTE(SUBSTITUTE(SUBSTITUTE(SUBSTITUTE(SUBSTITUTE(SUBSTITUTE(SUBSTITUTE(SUBSTITUTE(LOWER(CantoralDB[[#This Row],[Linked]]),"á","a"),"é","e"),"í","i"),"ó","o"),"ú","u")," ","_"),"¿",""),"?",""),"¡",""),"!",""),",","")&".html", SUBSTITUTE(SUBSTITUTE(SUBSTITUTE(SUBSTITUTE(SUBSTITUTE(SUBSTITUTE(SUBSTITUTE(SUBSTITUTE(SUBSTITUTE(SUBSTITUTE(SUBSTITUTE(LOWER(CantoralDB[[#This Row],[Título]]),"á","a"),"é","e"),"í","i"),"ó","o"),"ú","u")," ","_"),"¿",""),"?",""),"¡",""),"!",""),",","")&".html") -> canciones/ain_karem/yo_soy_el_que_vive.html | V2: https://open.spotify.com/intl-es/track/45hdRERkPk24IlujX4dlXq?si=4544995abc384cf4 | W2: =IF(CantoralDB[[#This Row],[Linked]]="X","","<li"& IF(CantoralDB[[#This Row],[Autor]]="-",""," data-author="""&CantoralDB[[#This Row],[Autor]]&"""")& IF(ISBLANK(CantoralDB[[#This Row],[Momento]]),""," data-momento="""&CantoralDB[[#This Row],[Momento]]&"""")& IF(ISBLANK(CantoralDB[[#This Row],[Número]]),""," data-nnew="""&CantoralDB[[#This Row],[Número]]&"""")& IF(ISBLANK(CantoralDB[[#This Row],[Número antiguo]]),""," data-nold="""&CantoralDB[[#This Row],[Número antiguo]]&"""")& IF(ISBLANK(CantoralDB[[#This Row],[Número RCC]]),""," data-nrcc="""&CantoralDB[[#This Row],[Número RCC]]&"""")& "><a href="""&CantoralDB[[#This Row],[Ruta]]&""">"&CantoralDB[[#This Row],[Título]]&"</a></li>") -> <li data-author="Ain Karem"><a href="canciones/ain_karem/yo_soy_el_que_vive.html">Yo soy el que vive</a></li> | X2: =_xlfn.TEXTBEFORE(_xlfn.TEXTAFTER(CantoralDB[[#This Row],[index.html]],">"),">")&">" -> <a href="canciones/ain_karem/yo_soy_el_que_vive.html">
A3: =ROW(CantoralDB[[#This Row],[Título]])-1 -> 2 | B3: Que se alegren tus entrañas | H3: La | I3: cej1 | J3: OK | M3: Ain Karem | N3: A todos los pueblos | O3: 2 | P3: 2010 | Q3: {=IF(OR(CantoralDB[[#This Row],[Autor]]="Taizé en español",CantoralDB[[#This Row],[Autor]]="Taizé original",CantoralDB[[#This Row],[Autor]]="Taizé"),"taize", IFERROR(_xlfn.XLOOKUP(CantoralDB[[#This Row],[Autor]],_xlfn.CHOOSECOLS(_xlfn.ANCHORARRAY(secciones!$A$3),1),_xlfn.CHOOSECOLS(_xlfn.ANCHORARRAY(secciones!$A$3),2)), IF(OR(CantoralDB[[#This Row],[Número antiguo]]<>"",CantoralDB[[#This Row],[Número]]<>""),"nsb","nuevas" )))} -> ain_karem | R3: {=IF(CantoralDB[[#This Row],[Autor]]="Taizé original","taize_orig", IF(CantoralDB[[#This Row],[Autor]]="Taizé en español","taize_esp", IF(CantoralDB[[#This Row],[Autor]]="Villancicos","villancicos", IF(OR(CantoralDB[[#This Row],[Número antiguo]]<>"",CantoralDB[[#This Row],[Número]]<>""),"nsb", IF(CantoralDB[[#This Row],[Número RCC]]<>"","rcce", IFERROR(_xlfn.XLOOKUP(CantoralDB[[#This Row],[Autor]],_xlfn.CHOOSECOLS(_xlfn.ANCHORARRAY(secciones!$A$3),1),_xlfn.CHOOSECOLS(_xlfn.ANCHORARRAY(secciones!$A$3),2)),"nuevas") )))))} -> ain_karem | S3: ="canciones/"&CantoralDB[[#This Row],[Carpeta]]&"/"&IF(CantoralDB[[#This Row],[Autor]]="Taizé en español", SUBSTITUTE(SUBSTITUTE(SUBSTITUTE(SUBSTITUTE(SUBSTITUTE(SUBSTITUTE(SUBSTITUTE(SUBSTITUTE(SUBSTITUTE(SUBSTITUTE(SUBSTITUTE(LOWER(CantoralDB[[#This Row],[Linked]]),"á","a"),"é","e"),"í","i"),"ó","o"),"ú","u")," ","_"),"¿",""),"?",""),"¡",""),"!",""),",","")&".html", SUBSTITUTE(SUBSTITUTE(SUBSTITUTE(SUBSTITUTE(SUBSTITUTE(SUBSTITUTE(SUBSTITUTE(SUBSTITUTE(SUBSTITUTE(SUBSTITUTE(SUBSTITUTE(LOWER(CantoralDB[[#This Row],[Título]]),"á","a"),"é","e"),"í","i"),"ó","o"),"ú","u")," ","_"),"¿",""),"?",""),"¡",""),"!",""),",","")&".html") -> canciones/ain_karem/que_se_alegren_tus_entrañas.html | V3: https://open.spotify.com/intl-es/track/5Fcz0xhDUSg7nUsrjFylAD?si=0d98458416ed4dbd | W3: =IF(CantoralDB[[#This Row],[Linked]]="X","","<li"& IF(CantoralDB[[#This Row],[Autor]]="-",""," data-author="""&CantoralDB[[#This Row],[Autor]]&"""")& IF(ISBLANK(CantoralDB[[#This Row],[Momento]]),""," data-momento="""&CantoralDB[[#This Row],[Momento]]&"""")& IF(ISBLANK(CantoralDB[[#This Row],[Número]]),""," data-nnew="""&CantoralDB[[#This Row],[Número]]&"""")& IF(ISBLANK(CantoralDB[[#This Row],[Número antiguo]]),""," data-nold="""&CantoralDB[[#This Row],[Número antiguo]]&"""")& IF(ISBLANK(CantoralDB[[#This Row],[Número RCC]]),""," data-nrcc="""&CantoralDB[[#This Row],[Número RCC]]&"""")& "><a href="""&CantoralDB[[#This Row],[Ruta]]&""">"&CantoralDB[[#This Row],[Título]]&"</a></li>") -> <li data-author="Ain Karem"><a href="canciones/ain_karem/que_se_alegren_tus_entrañas.html">Que se alegren tus entrañas</a></li> | X3: =_xlfn.TEXTBEFORE(_xlfn.TEXTAFTER(CantoralDB[[#This Row],[index.html]],">"),">")&">" -> <a href="canciones/ain_karem/que_se_alegren_tus_entrañas.html">
A4: =ROW(CantoralDB[[#This Row],[Título]])-1 -> 3 | B4: Palabra | H4: Do | I4: cej5 | J4: OK | M4: Ain Karem | N4: A todos los pueblos | O4: 3 | P4: 2010 | Q4: {=IF(OR(CantoralDB[[#This Row],[Autor]]="Taizé en español",CantoralDB[[#This Row],[Autor]]="Taizé original",CantoralDB[[#This Row],[Autor]]="Taizé"),"taize", IFERROR(_xlfn.XLOOKUP(CantoralDB[[#This Row],[Autor]],_xlfn.CHOOSECOLS(_xlfn.ANCHORARRAY(secciones!$A$3),1),_xlfn.CHOOSECOLS(_xlfn.ANCHORARRAY(secciones!$A$3),2)), IF(OR(CantoralDB[[#This Row],[Número antiguo]]<>"",CantoralDB[[#This Row],[Número]]<>""),"nsb","nuevas" )))} -> ain_karem | R4: {=IF(CantoralDB[[#This Row],[Autor]]="Taizé original","taize_orig", IF(CantoralDB[[#This Row],[Autor]]="Taizé en español","taize_esp", IF(CantoralDB[[#This Row],[Autor]]="Villancicos","villancicos", IF(OR(CantoralDB[[#This Row],[Número antiguo]]<>"",CantoralDB[[#This Row],[Número]]<>""),"nsb", IF(CantoralDB[[#This Row],[Número RCC]]<>"","rcce", IFERROR(_xlfn.XLOOKUP(CantoralDB[[#This Row],[Autor]],_xlfn.CHOOSECOLS(_xlfn.ANCHORARRAY(secciones!$A$3),1),_xlfn.CHOOSECOLS(_xlfn.ANCHORARRAY(secciones!$A$3),2)),"nuevas") )))))} -> ain_karem | S4: ="canciones/"&CantoralDB[[#This Row],[Carpeta]]&"/"&IF(CantoralDB[[#This Row],[Autor]]="Taizé en español", SUBSTITUTE(SUBSTITUTE(SUBSTITUTE(SUBSTITUTE(SUBSTITUTE(SUBSTITUTE(SUBSTITUTE(SUBSTITUTE(SUBSTITUTE(SUBSTITUTE(SUBSTITUTE(LOWER(CantoralDB[[#This Row],[Linked]]),"á","a"),"é","e"),"í","i"),"ó","o"),"ú","u")," ","_"),"¿",""),"?",""),"¡",""),"!",""),",","")&".html", SUBSTITUTE(SUBSTITUTE(SUBSTITUTE(SUBSTITUTE(SUBSTITUTE(SUBSTITUTE(SUBSTITUTE(SUBSTITUTE(SUBSTITUTE(SUBSTITUTE(SUBSTITUTE(LOWER(CantoralDB[[#This Row],[Título]]),"á","a"),"é","e"),"í","i"),"ó","o"),"ú","u")," ","_"),"¿",""),"?",""),"¡",""),"!",""),",","")&".html") -> canciones/ain_karem/palabra.html | V4: https://open.spotify.com/intl-es/track/6IbstxKB9xS9RuQqDYTMks?si=823f8686723b438c | W4: =IF(CantoralDB[[#This Row],[Linked]]="X","","<li"& IF(CantoralDB[[#This Row],[Autor]]="-",""," data-author="""&CantoralDB[[#This Row],[Autor]]&"""")& IF(ISBLANK(CantoralDB[[#This Row],[Momento]]),""," data-momento="""&CantoralDB[[#This Row],[Momento]]&"""")& IF(ISBLANK(CantoralDB[[#This Row],[Número]]),""," data-nnew="""&CantoralDB[[#This Row],[Número]]&"""")& IF(ISBLANK(CantoralDB[[#This Row],[Número antiguo]]),""," data-nold="""&CantoralDB[[#This Row],[Número antiguo]]&"""")& IF(ISBLANK(CantoralDB[[#This Row],[Número RCC]]),""," data-nrcc="""&CantoralDB[[#This Row],[Número RCC]]&"""")& "><a href="""&CantoralDB[[#This Row],[Ruta]]&""">"&CantoralDB[[#This Row],[Título]]&"</a></li>") -> <li data-author="Ain Karem"><a href="canciones/ain_karem/palabra.html">Palabra</a></li> | X4: =_xlfn.TEXTBEFORE(_xlfn.TEXTAFTER(CantoralDB[[#This Row],[index.html]],">"),">")&">" -> <a href="canciones/ain_karem/palabra.html">
A5: =ROW(CantoralDB[[#This Row],[Título]])-1 -> 4 | B5: Atraviesas | H5: Re | I5: cej3 | J5: OK | M5: Ain Karem | N5: A todos los pueblos | O5: 4 | P5: 2010 | Q5: {=IF(OR(CantoralDB[[#This Row],[Autor]]="Taizé en español",CantoralDB[[#This Row],[Autor]]="Taizé original",CantoralDB[[#This Row],[Autor]]="Taizé"),"taize", IFERROR(_xlfn.XLOOKUP(CantoralDB[[#This Row],[Autor]],_xlfn.CHOOSECOLS(_xlfn.ANCHORARRAY(secciones!$A$3),1),_xlfn.CHOOSECOLS(_xlfn.ANCHORARRAY(secciones!$A$3),2)), IF(OR(CantoralDB[[#This Row],[Número antiguo]]<>"",CantoralDB[[#This Row],[Número]]<>""),"nsb","nuevas" )))} -> ain_karem | R5: {=IF(CantoralDB[[#This Row],[Autor]]="Taizé original","taize_orig", IF(CantoralDB[[#This Row],[Autor]]="Taizé en español","taize_esp", IF(CantoralDB[[#This Row],[Autor]]="Villancicos","villancicos", IF(OR(CantoralDB[[#This Row],[Número antiguo]]<>"",CantoralDB[[#This Row],[Número]]<>""),"nsb", IF(CantoralDB[[#This Row],[Número RCC]]<>"","rcce", IFERROR(_xlfn.XLOOKUP(CantoralDB[[#This Row],[Autor]],_xlfn.CHOOSECOLS(_xlfn.ANCHORARRAY(secciones!$A$3),1),_xlfn.CHOOSECOLS(_xlfn.ANCHORARRAY(secciones!$A$3),2)),"nuevas") )))))} -> ain_karem | S5: ="canciones/"&CantoralDB[[#This Row],[Carpeta]]&"/"&IF(CantoralDB[[#This Row],[Autor]]="Taizé en español", SUBSTITUTE(SUBSTITUTE(SUBSTITUTE(SUBSTITUTE(SUBSTITUTE(SUBSTITUTE(SUBSTITUTE(SUBSTITUTE(SUBSTITUTE(SUBSTITUTE(SUBSTITUTE(LOWER(CantoralDB[[#This Row],[Linked]]),"á","a"),"é","e"),"í","i"),"ó","o"),"ú","u")," ","_"),"¿",""),"?",""),"¡",""),"!",""),",","")&".html", SUBSTITUTE(SUBSTITUTE(SUBSTITUTE(SUBSTITUTE(SUBSTITUTE(SUBSTITUTE(SUBSTITUTE(SUBSTITUTE(SUBSTITUTE(SUBSTITUTE(SUBSTITUTE(LOWER(CantoralDB[[#This Row],[Título]]),"á","a"),"é","e"),"í","i"),"ó","o"),"ú","u")," ","_"),"¿",""),"?",""),"¡",""),"!",""),",","")&".html") -> canciones/ain_karem/atraviesas.html | V5: https://open.spotify.com/intl-es/track/61c2KYQwdLDXO8i1jquizI?si=d911c8eb8adc4bb3 | W5: =IF(CantoralDB[[#This Row],[Linked]]="X","","<li"& IF(CantoralDB[[#This Row],[Autor]]="-",""," data-author="""&CantoralDB[[#This Row],[Autor]]&"""")& IF(ISBLANK(CantoralDB[[#This Row],[Momento]]),""," data-momento="""&CantoralDB[[#This Row],[Momento]]&"""")& IF(ISBLANK(CantoralDB[[#This Row],[Número]]),""," data-nnew="""&CantoralDB[[#This Row],[Número]]&"""")& IF(ISBLANK(CantoralDB[[#This Row],[Número antiguo]]),""," data-nold="""&CantoralDB[[#This Row],[Número antiguo]]&"""")& IF(ISBLANK(CantoralDB[[#This Row],[Número RCC]]),""," data-nrcc="""&CantoralDB[[#This Row],[Número RCC]]&"""")& "><a href="""&CantoralDB[[#This Row],[Ruta]]&""">"&CantoralDB[[#This Row],[Título]]&"</a></li>") -> <li data-author="Ain Karem"><a href="canciones/ain_karem/atraviesas.html">Atraviesas</a></li> | X5: =_xlfn.TEXTBEFORE(_xlfn.TEXTAFTER(CantoralDB[[#This Row],[index.html]],">"),">")&">" -> <a href="canciones/ain_karem/atraviesas.html">
A6: =ROW(CantoralDB[[#This Row],[Título]])-1 -> 5 | B6: Los incontables | H6: Do | I6: cej3 | J6: OK | M6: Ain Karem | N6: A todos los pueblos | O6: 5 | P6: 2010 | Q6: {=IF(OR(CantoralDB[[#This Row],[Autor]]="Taizé en español",CantoralDB[[#This Row],[Autor]]="Taizé original",CantoralDB[[#This Row],[Autor]]="Taizé"),"taize", IFERROR(_xlfn.XLOOKUP(CantoralDB[[#This Row],[Autor]],_xlfn.CHOOSECOLS(_xlfn.ANCHORARRAY(secciones!$A$3),1),_xlfn.CHOOSECOLS(_xlfn.ANCHORARRAY(secciones!$A$3),2)), IF(OR(CantoralDB[[#This Row],[Número antiguo]]<>"",CantoralDB[[#This Row],[Número]]<>""),"nsb","nuevas" )))} -> ain_karem | R6: {=IF(CantoralDB[[#This Row],[Autor]]="Taizé original","taize_orig", IF(CantoralDB[[#This Row],[Autor]]="Taizé en español","taize_esp", IF(CantoralDB[[#This Row],[Autor]]="Villancicos","villancicos", IF(OR(CantoralDB[[#This Row],[Número antiguo]]<>"",CantoralDB[[#This Row],[Número]]<>""),"nsb", IF(CantoralDB[[#This Row],[Número RCC]]<>"","rcce", IFERROR(_xlfn.XLOOKUP(CantoralDB[[#This Row],[Autor]],_xlfn.CHOOSECOLS(_xlfn.ANCHORARRAY(secciones!$A$3),1),_xlfn.CHOOSECOLS(_xlfn.ANCHORARRAY(secciones!$A$3),2)),"nuevas") )))))} -> ain_karem | S6: ="canciones/"&CantoralDB[[#This Row],[Carpeta]]&"/"&IF(CantoralDB[[#This Row],[Autor]]="Taizé en español", SUBSTITUTE(SUBSTITUTE(SUBSTITUTE(SUBSTITUTE(SUBSTITUTE(SUBSTITUTE(SUBSTITUTE(SUBSTITUTE(SUBSTITUTE(SUBSTITUTE(SUBSTITUTE(LOWER(CantoralDB[[#This Row],[Linked]]),"á","a"),"é","e"),"í","i"),"ó","o"),"ú","u")," ","_"),"¿",""),"?",""),"¡",""),"!",""),",","")&".html", SUBSTITUTE(SUBSTITUTE(SUBSTITUTE(SUBSTITUTE(SUBSTITUTE(SUBSTITUTE(SUBSTITUTE(SUBSTITUTE(SUBSTITUTE(SUBSTITUTE(SUBSTITUTE(LOWER(CantoralDB[[#This Row],[Título]]),"á","a"),"é","e"),"í","i"),"ó","o"),"ú","u")," ","_"),"¿",""),"?",""),"¡",""),"!",""),",","")&".html") -> canciones/ain_karem/los_incontables.html | V6: https://open.spotify.com/intl-es/track/1kITt1STB7aHSkauwzNJCs?si=fb887986370844d7 | W6: =IF(CantoralDB[[#This Row],[Linked]]="X","","<li"& IF(CantoralDB[[#This Row],[Autor]]="-",""," data-author="""&CantoralDB[[#This Row],[Autor]]&"""")& IF(ISBLANK(CantoralDB[[#This Row],[Momento]]),""," data-momento="""&CantoralDB[[#This Row],[Momento]]&"""")& IF(ISBLANK(CantoralDB[[#This Row],[Número]]),""," data-nnew="""&CantoralDB[[#This Row],[Número]]&"""")& IF(ISBLANK(CantoralDB[[#This Row],[Número antiguo]]),""," data-nold="""&CantoralDB[[#This Row],[Número antiguo]]&"""")& IF(ISBLANK(CantoralDB[[#This Row],[Número RCC]]),""," data-nrcc="""&CantoralDB[[#This Row],[Número RCC]]&"""")& "><a href="""&CantoralDB[[#This Row],[Ruta]]&""">"&CantoralDB[[#This Row],[Título]]&"</a></li>") -> <li data-author="Ain Karem"><a href="canciones/ain_karem/los_incontables.html">Los incontables</a></li> | X6: =_xlfn.TEXTBEFORE(_xlfn.TEXTAFTER(CantoralDB[[#This Row],[index.html]],">"),">")&">" -> <a href="canciones/ain_karem/los_incontables.html">
A7: =ROW(CantoralDB[[#This Row],[Título]])-1 -> 6 | B7: He venido a servir | C7: Antífonas | D7: D20 | G7: NSB | H7: Sol | I7: cej2 | J7: OK | M7: Ain Karem | N7: A todos los pueblos | O7: 6 | P7: 2010 | Q7: {=IF(OR(CantoralDB[[#This Row],[Autor]]="Taizé en español",CantoralDB[[#This Row],[Autor]]="Taizé original",CantoralDB[[#This Row],[Autor]]="Taizé"),"taize", IFERROR(_xlfn.XLOOKUP(CantoralDB[[#This Row],[Autor]],_xlfn.CHOOSECOLS(_xlfn.ANCHORARRAY(secciones!$A$3),1),_xlfn.CHOOSECOLS(_xlfn.ANCHORARRAY(secciones!$A$3),2)), IF(OR(CantoralDB[[#This Row],[Número antiguo]]<>"",CantoralDB[[#This Row],[Número]]<>""),"nsb","nuevas" )))} -> ain_karem | R7: {=IF(CantoralDB[[#This Row],[Autor]]="Taizé original","taize_orig", IF(CantoralDB[[#This Row],[Autor]]="Taizé en español","taize_esp", IF(CantoralDB[[#This Row],[Autor]]="Villancicos","villancicos", IF(OR(CantoralDB[[#This Row],[Número antiguo]]<>"",CantoralDB[[#This Row],[Número]]<>""),"nsb", IF(CantoralDB[[#This Row],[Número RCC]]<>"","rcce", IFERROR(_xlfn.XLOOKUP(CantoralDB[[#This Row],[Autor]],_xlfn.CHOOSECOLS(_xlfn.ANCHORARRAY(secciones!$A$3),1),_xlfn.CHOOSECOLS(_xlfn.ANCHORARRAY(secciones!$A$3),2)),"nuevas") )))))} -> nsb | S7: ="canciones/"&CantoralDB[[#This Row],[Carpeta]]&"/"&IF(CantoralDB[[#This Row],[Autor]]="Taizé en español", SUBSTITUTE(SUBSTITUTE(SUBSTITUTE(SUBSTITUTE(SUBSTITUTE(SUBSTITUTE(SUBSTITUTE(SUBSTITUTE(SUBSTITUTE(SUBSTITUTE(SUBSTITUTE(LOWER(CantoralDB[[#This Row],[Linked]]),"á","a"),"é","e"),"í","i"),"ó","o"),"ú","u")," ","_"),"¿",""),"?",""),"¡",""),"!",""),",","")&".html", SUBSTITUTE(SUBSTITUTE(SUBSTITUTE(SUBSTITUTE(SUBSTITUTE(SUBSTITUTE(SUBSTITUTE(SUBSTITUTE(SUBSTITUTE(SUBSTITUTE(SUBSTITUTE(LOWER(CantoralDB[[#This Row],[Título]]),"á","a"),"é","e"),"í","i"),"ó","o"),"ú","u")," ","_"),"¿",""),"?",""),"¡",""),"!",""),",","")&".html") -> canciones/ain_karem/he_venido_a_servir.html | T7: Mateo 20, 26-28 | V7: https://open.spotify.com/intl-es/track/1F0uLNlzSh6sN3COwrprqD?si=c753a1de92464054 | W7: =IF(CantoralDB[[#This Row],[Linked]]="X","","<li"& IF(CantoralDB[[#This Row],[Autor]]="-",""," data-author="""&CantoralDB[[#This Row],[Autor]]&"""")& IF(ISBLANK(CantoralDB[[#This Row],[Momento]]),""," data-momento="""&CantoralDB[[#This Row],[Momento]]&"""")& IF(ISBLANK(CantoralDB[[#This Row],[Número]]),""," data-nnew="""&CantoralDB[[#This Row],[Número]]&"""")& IF(ISBLANK(CantoralDB[[#This Row],[Número antiguo]]),""," data-nold="""&CantoralDB[[#This Row],[Número antiguo]]&"""")& IF(ISBLANK(CantoralDB[[#This Row],[Número RCC]]),""," data-nrcc="""&CantoralDB[[#This Row],[Número RCC]]&"""")& "><a href="""&CantoralDB[[#This Row],[Ruta]]&""">"&CantoralDB[[#This Row],[Título]]&"</a></li>") -> <li data-author="Ain Karem" data-momento="Antífonas" data-nnew="D20"><a href="canciones/ain_karem/he_venido_a_servir.html">He venido a servir</a></li> | X7: =_xlfn.TEXTBEFORE(_xlfn.TEXTAFTER(CantoralDB[[#This Row],[index.html]],">"),">")&">" -> <a href="canciones/ain_karem/he_venido_a_servir.html">
A8: =ROW(CantoralDB[[#This Row],[Título]])-1 -> 7 | B8: Palabra encarnada | H8: La | I8: cej2 | J8: OK | M8: Ain Karem | N8: A todos los pueblos | O8: 7 | P8: 2010 | Q8: {=IF(OR(CantoralDB[[#This Row],[Autor]]="Taizé en español",CantoralDB[[#This Row],[Autor]]="Taizé original",CantoralDB[[#This Row],[Autor]]="Taizé"),"taize", IFERROR(_xlfn.XLOOKUP(CantoralDB[[#This Row],[Autor]],_xlfn.CHOOSECOLS(_xlfn.ANCHORARRAY(secciones!$A$3),1),_xlfn.CHOOSECOLS(_xlfn.ANCHORARRAY(secciones!$A$3),2)), IF(OR(CantoralDB[[#This Row],[Número antiguo]]<>"",CantoralDB[[#This Row],[Número]]<>""),"nsb","nuevas" )))} -> ain_karem | R8: {=IF(CantoralDB[[#This Row],[Autor]]="Taizé original","taize_orig", IF(CantoralDB[[#This Row],[Autor]]="Taizé en español","taize_esp", IF(CantoralDB[[#This Row],[Autor]]="Villancicos","villancicos", IF(OR(CantoralDB[[#This Row],[Número antiguo]]<>"",CantoralDB[[#This Row],[Número]]<>""),"nsb", IF(CantoralDB[[#This Row],[Número RCC]]<>"","rcce", IFERROR(_xlfn.XLOOKUP(CantoralDB[[#This Row],[Autor]],_xlfn.CHOOSECOLS(_xlfn.ANCHORARRAY(secciones!$A$3),1),_xlfn.CHOOSECOLS(_xlfn.ANCHORARRAY(secciones!$A$3),2)),"nuevas") )))))} -> ain_karem | S8: ="canciones/"&CantoralDB[[#This Row],[Carpeta]]&"/"&IF(CantoralDB[[#This Row],[Autor]]="Taizé en español", SUBSTITUTE(SUBSTITUTE(SUBSTITUTE(SUBSTITUTE(SUBSTITUTE(SUBSTITUTE(SUBSTITUTE(SUBSTITUTE(SUBSTITUTE(SUBSTITUTE(SUBSTITUTE(LOWER(CantoralDB[[#This Row],[Linked]]),"á","a"),"é","e"),"í","i"),"ó","o"),"ú","u")," ","_"),"¿",""),"?",""),"¡",""),"!",""),",","")&".html", SUBSTITUTE(SUBSTITUTE(SUBSTITUTE(SUBSTITUTE(SUBSTITUTE(SUBSTITUTE(SUBSTITUTE(SUBSTITUTE(SUBSTITUTE(SUBSTITUTE(SUBSTITUTE(LOWER(CantoralDB[[#This Row],[Título]]),"á","a"),"é","e"),"í","i"),"ó","o"),"ú","u")," ","_"),"¿",""),"?",""),"¡",""),"!",""),",","")&".html") -> canciones/ain_karem/palabra_encarnada.html | V8: https://open.spotify.com/intl-es/track/5qspUpcBqHzdozbLPrCSFZ?si=7849e67df0ac418f | W8: =IF(CantoralDB[[#This Row],[Linked]]="X","","<li"& IF(CantoralDB[[#This Row],[Autor]]="-",""," data-author="""&CantoralDB[[#This Row],[Autor]]&"""")& IF(ISBLANK(CantoralDB[[#This Row],[Momento]]),""," data-momento="""&CantoralDB[[#This Row],[Momento]]&"""")& IF(ISBLANK(CantoralDB[[#This Row],[Número]]),""," data-nnew="""&CantoralDB[[#This Row],[Número]]&"""")& IF(ISBLANK(CantoralDB[[#This Row],[Número antiguo]]),""," data-nold="""&CantoralDB[[#This Row],[Número antiguo]]&"""")& IF(ISBLANK(CantoralDB[[#This Row],[Número RCC]]),""," data-nrcc="""&CantoralDB[[#This Row],[Número RCC]]&"""")& "><a href="""&CantoralDB[[#This Row],[Ruta]]&""">"&CantoralDB[[#This Row],[Título]]&"</a></li>") -> <li data-author="Ain Karem"><a href="canciones/ain_karem/palabra_encarnada.html">Palabra encarnada</a></li> | X8: =_xlfn.TEXTBEFORE(_xlfn.TEXTAFTER(CantoralDB[[#This Row],[index.html]],">"),">")&">" -> <a href="canciones/ain_karem/palabra_encarnada.html">
A9: =ROW(CantoralDB[[#This Row],[Título]])-1 -> 8 | B9: Kolokoso | H9: Re | M9: Ain Karem | N9: A todos los pueblos | O9: 8 | P9: 2010 | Q9: {=IF(OR(CantoralDB[[#This Row],[Autor]]="Taizé en español",CantoralDB[[#This Row],[Autor]]="Taizé original",CantoralDB[[#This Row],[Autor]]="Taizé"),"taize", IFERROR(_xlfn.XLOOKUP(CantoralDB[[#This Row],[Autor]],_xlfn.CHOOSECOLS(_xlfn.ANCHORARRAY(secciones!$A$3),1),_xlfn.CHOOSECOLS(_xlfn.ANCHORARRAY(secciones!$A$3),2)), IF(OR(CantoralDB[[#This Row],[Número antiguo]]<>"",CantoralDB[[#This Row],[Número]]<>""),"nsb","nuevas" )))} -> ain_karem | R9: {=IF(CantoralDB[[#This Row],[Autor]]="Taizé original","taize_orig", IF(CantoralDB[[#This Row],[Autor]]="Taizé en español","taize_esp", IF(CantoralDB[[#This Row],[Autor]]="Villancicos","villancicos", IF(OR(CantoralDB[[#This Row],[Número antiguo]]<>"",CantoralDB[[#This Row],[Número]]<>""),"nsb", IF(CantoralDB[[#This Row],[Número RCC]]<>"","rcce", IFERROR(_xlfn.XLOOKUP(CantoralDB[[#This Row],[Autor]],_xlfn.CHOOSECOLS(_xlfn.ANCHORARRAY(secciones!$A$3),1),_xlfn.CHOOSECOLS(_xlfn.ANCHORARRAY(secciones!$A$3),2)),"nuevas") )))))} -> ain_karem | S9: ="canciones/"&CantoralDB[[#This Row],[Carpeta]]&"/"&IF(CantoralDB[[#This Row],[Autor]]="Taizé en español", SUBSTITUTE(SUBSTITUTE(SUBSTITUTE(SUBSTITUTE(SUBSTITUTE(SUBSTITUTE(SUBSTITUTE(SUBSTITUTE(SUBSTITUTE(SUBSTITUTE(SUBSTITUTE(LOWER(CantoralDB[[#This Row],[Linked]]),"á","a"),"é","e"),"í","i"),"ó","o"),"ú","u")," ","_"),"¿",""),"?",""),"¡",""),"!",""),",","")&".html", SUBSTITUTE(SUBSTITUTE(SUBSTITUTE(SUBSTITUTE(SUBSTITUTE(SUBSTITUTE(SUBSTITUTE(SUBSTITUTE(SUBSTITUTE(SUBSTITUTE(SUBSTITUTE(LOWER(CantoralDB[[#This Row],[Título]]),"á","a"),"é","e"),"í","i"),"ó","o"),"ú","u")," ","_"),"¿",""),"?",""),"¡",""),"!",""),",","")&".html") -> canciones/ain_karem/kolokoso.html | V9: https://open.spotify.com/intl-es/track/0iEwaEXoK5F9G01lCuIsg3?si=0e8a1509bc20468c | W9: =IF(CantoralDB[[#This Row],[Linked]]="X","","<li"& IF(CantoralDB[[#This Row],[Autor]]="-",""," data-author="""&CantoralDB[[#This Row],[Autor]]&"""")& IF(ISBLANK(CantoralDB[[#This Row],[Momento]]),""," data-momento="""&CantoralDB[[#This Row],[Momento]]&"""")& IF(ISBLANK(CantoralDB[[#This Row],[Número]]),""," data-nnew="""&CantoralDB[[#This Row],[Número]]&"""")& IF(ISBLANK(CantoralDB[[#This Row],[Número antiguo]]),""," data-nold="""&CantoralDB[[#This Row],[Número antiguo]]&"""")& IF(ISBLANK(CantoralDB[[#This Row],[Número RCC]]),""," data-nrcc="""&CantoralDB[[#This Row],[Número RCC]]&"""")& "><a href="""&CantoralDB[[#This Row],[Ruta]]&""">"&CantoralDB[[#This Row],[Título]]&"</a></li>") -> <li data-author="Ain Karem"><a href="canciones/ain_karem/kolokoso.html">Kolokoso</a></li> | X9: =_xlfn.TEXTBEFORE(_xlfn.TEXTAFTER(CantoralDB[[#This Row],[index.html]],">"),">")&">" -> <a href="canciones/ain_karem/kolokoso.html">
A10: =ROW(CantoralDB[[#This Row],[Título]])-1 -> 9 | B10: La mujer cananea | H10: Sol | I10: cej5 | J10: OK | M10: Ain Karem | N10: A todos los pueblos | O10: 9 | P10: 2010 | Q10: {=IF(OR(CantoralDB[[#This Row],[Autor]]="Taizé en español",CantoralDB[[#This Row],[Autor]]="Taizé original",CantoralDB[[#This Row],[Autor]]="Taizé"),"taize", IFERROR(_xlfn.XLOOKUP(CantoralDB[[#This Row],[Autor]],_xlfn.CHOOSECOLS(_xlfn.ANCHORARRAY(secciones!$A$3),1),_xlfn.CHOOSECOLS(_xlfn.ANCHORARRAY(secciones!$A$3),2)), IF(OR(CantoralDB[[#This Row],[Número antiguo]]<>"",CantoralDB[[#This Row],[Número]]<>""),"nsb","nuevas" )))} -> ain_karem | R10: {=IF(CantoralDB[[#This Row],[Autor]]="Taizé original","taize_orig", IF(CantoralDB[[#This Row],[Autor]]="Taizé en español","taize_esp", IF(CantoralDB[[#This Row],[Autor]]="Villancicos","villancicos", IF(OR(CantoralDB[[#This Row],[Número antiguo]]<>"",CantoralDB[[#This Row],[Número]]<>""),"nsb", IF(CantoralDB[[#This Row],[Número RCC]]<>"","rcce", IFERROR(_xlfn.XLOOKUP(CantoralDB[[#This Row],[Autor]],_xlfn.CHOOSECOLS(_xlfn.ANCHORARRAY(secciones!$A$3),1),_xlfn.CHOOSECOLS(_xlfn.ANCHORARRAY(secciones!$A$3),2)),"nuevas") )))))} -> ain_karem | S10: ="canciones/"&CantoralDB[[#This Row],[Carpeta]]&"/"&IF(CantoralDB[[#This Row],[Autor]]="Taizé en español", SUBSTITUTE(SUBSTITUTE(SUBSTITUTE(SUBSTITUTE(SUBSTITUTE(SUBSTITUTE(SUBSTITUTE(SUBSTITUTE(SUBSTITUTE(SUBSTITUTE(SUBSTITUTE(LOWER(CantoralDB[[#This Row],[Linked]]),"á","a"),"é","e"),"í","i"),"ó","o"),"ú","u")," ","_"),"¿",""),"?",""),"¡",""),"!",""),",","")&".html", SUBSTITUTE(SUBSTITUTE(SUBSTITUTE(SUBSTITUTE(SUBSTITUTE(SUBSTITUTE(SUBSTITUTE(SUBSTITUTE(SUBSTITUTE(SUBSTITUTE(SUBSTITUTE(LOWER(CantoralDB[[#This Row],[Título]]),"á","a"),"é","e"),"í","i"),"ó","o"),"ú","u")," ","_"),"¿",""),"?",""),"¡",""),"!",""),",","")&".html") -> canciones/ain_karem/la_mujer_cananea.html | V10: https://open.spotify.com/intl-es/track/0e4gJvX84bIefNwMWLoCAX?si=80b816c7eb584408 | W10: =IF(CantoralDB[[#This Row],[Linked]]="X","","<li"& IF(CantoralDB[[#This Row],[Autor]]="-",""," data-author="""&CantoralDB[[#This Row],[Autor]]&"""")& IF(ISBLANK(CantoralDB[[#This Row],[Momento]]),""," data-momento="""&CantoralDB[[#This Row],[Momento]]&"""")& IF(ISBLANK(CantoralDB[[#This Row],[Número]]),""," data-nnew="""&CantoralDB[[#This Row],[Número]]&"""")& IF(ISBLANK(CantoralDB[[#This Row],[Número antiguo]]),""," data-nold="""&CantoralDB[[#This Row],[Número antiguo]]&"""")& IF(ISBLANK(CantoralDB[[#This Row],[Número RCC]]),""," data-nrcc="""&CantoralDB[[#This Row],[Número RCC]]&"""")& "><a href="""&CantoralDB[[#This Row],[Ruta]]&""">"&CantoralDB[[#This Row],[Título]]&"</a></li>") -> <li data-author="Ain Karem"><a href="canciones/ain_karem/la_mujer_cananea.html">La mujer cananea</a></li> | X10: =_xlfn.TEXTBEFORE(_xlfn.TEXTAFTER(CantoralDB[[#This Row],[index.html]],">"),">")&">" -> <a href="canciones/ain_karem/la_mujer_cananea.html">
A11: =ROW(CantoralDB[[#This Row],[Título]])-1 -> 10 | B11: El siervo | H11: Fa | J11: OK | M11: Ain Karem | N11: A todos los pueblos | O11: 10 | P11: 2010 | Q11: {=IF(OR(CantoralDB[[#This Row],[Autor]]="Taizé en español",CantoralDB[[#This Row],[Autor]]="Taizé original",CantoralDB[[#This Row],[Autor]]="Taizé"),"taize", IFERROR(_xlfn.XLOOKUP(CantoralDB[[#This Row],[Autor]],_xlfn.CHOOSECOLS(_xlfn.ANCHORARRAY(secciones!$A$3),1),_xlfn.CHOOSECOLS(_xlfn.ANCHORARRAY(secciones!$A$3),2)), IF(OR(CantoralDB[[#This Row],[Número antiguo]]<>"",CantoralDB[[#This Row],[Número]]<>""),"nsb","nuevas" )))} -> ain_karem | R11: {=IF(CantoralDB[[#This Row],[Autor]]="Taizé original","taize_orig", IF(CantoralDB[[#This Row],[Autor]]="Taizé en español","taize_esp", IF(CantoralDB[[#This Row],[Autor]]="Villancicos","villancicos", IF(OR(CantoralDB[[#This Row],[Número antiguo]]<>"",CantoralDB[[#This Row],[Número]]<>""),"nsb", IF(CantoralDB[[#This Row],[Número RCC]]<>"","rcce", IFERROR(_xlfn.XLOOKUP(CantoralDB[[#This Row],[Autor]],_xlfn.CHOOSECOLS(_xlfn.ANCHORARRAY(secciones!$A$3),1),_xlfn.CHOOSECOLS(_xlfn.ANCHORARRAY(secciones!$A$3),2)),"nuevas") )))))} -> ain_karem | S11: ="canciones/"&CantoralDB[[#This Row],[Carpeta]]&"/"&IF(CantoralDB[[#This Row],[Autor]]="Taizé en español", SUBSTITUTE(SUBSTITUTE(SUBSTITUTE(SUBSTITUTE(SUBSTITUTE(SUBSTITUTE(SUBSTITUTE(SUBSTITUTE(SUBSTITUTE(SUBSTITUTE(SUBSTITUTE(LOWER(CantoralDB[[#This Row],[Linked]]),"á","a"),"é","e"),"í","i"),"ó","o"),"ú","u")," ","_"),"¿",""),"?",""),"¡",""),"!",""),",","")&".html", SUBSTITUTE(SUBSTITUTE(SUBSTITUTE(SUBSTITUTE(SUBSTITUTE(SUBSTITUTE(SUBSTITUTE(SUBSTITUTE(SUBSTITUTE(SUBSTITUTE(SUBSTITUTE(LOWER(CantoralDB[[#This Row],[Título]]),"á","a"),"é","e"),"í","i"),"ó","o"),"ú","u")," ","_"),"¿",""),"?",""),"¡",""),"!",""),",","")&".html") -> canciones/ain_karem/el_siervo.html | V11: https://open.spotify.com/intl-es/track/4uJP6RGSfzBkoXfm8CACfz?si=73a58ca5c1414e95 | W11: =IF(CantoralDB[[#This Row],[Linked]]="X","","<li"& IF(CantoralDB[[#This Row],[Autor]]="-",""," data-author="""&CantoralDB[[#This Row],[Autor]]&"""")& IF(ISBLANK(CantoralDB[[#This Row],[Momento]]),""," data-momento="""&CantoralDB[[#This Row],[Momento]]&"""")& IF(ISBLANK(CantoralDB[[#This Row],[Número]]),""," data-nnew="""&CantoralDB[[#This Row],[Número]]&"""")& IF(ISBLANK(CantoralDB[[#This Row],[Número antiguo]]),""," data-nold="""&CantoralDB[[#This Row],[Número antiguo]]&"""")& IF(ISBLANK(CantoralDB[[#This Row],[Número RCC]]),""," data-nrcc="""&CantoralDB[[#This Row],[Número RCC]]&"""")& "><a href="""&CantoralDB[[#This Row],[Ruta]]&""">"&CantoralDB[[#This Row],[Título]]&"</a></li>") -> <li data-author="Ain Karem"><a href="canciones/ain_karem/el_siervo.html">El siervo</a></li> | X11: =_xlfn.TEXTBEFORE(_xlfn.TEXTAFTER(CantoralDB[[#This Row],[index.html]],">"),">")&">" -> <a href="canciones/ain_karem/el_siervo.html">
A12: =ROW(CantoralDB[[#This Row],[Título]])-1 -> 11 | B12: La moneda perdida | H12: Re | J12: OK | M12: Ain Karem | N12: A todos los pueblos | O12: 11 | P12: 2010 | Q12: {=IF(OR(CantoralDB[[#This Row],[Autor]]="Taizé en español",CantoralDB[[#This Row],[Autor]]="Taizé original",CantoralDB[[#This Row],[Autor]]="Taizé"),"taize", IFERROR(_xlfn.XLOOKUP(CantoralDB[[#This Row],[Autor]],_xlfn.CHOOSECOLS(_xlfn.ANCHORARRAY(secciones!$A$3),1),_xlfn.CHOOSECOLS(_xlfn.ANCHORARRAY(secciones!$A$3),2)), IF(OR(CantoralDB[[#This Row],[Número antiguo]]<>"",CantoralDB[[#This Row],[Número]]<>""),"nsb","nuevas" )))} -> ain_karem | R12: {=IF(CantoralDB[[#This Row],[Autor]]="Taizé original","taize_orig", IF(CantoralDB[[#This Row],[Autor]]="Taizé en español","taize_esp", IF(CantoralDB[[#This Row],[Autor]]="Villancicos","villancicos", IF(OR(CantoralDB[[#This Row],[Número antiguo]]<>"",CantoralDB[[#This Row],[Número]]<>""),"nsb", IF(CantoralDB[[#This Row],[Número RCC]]<>"","rcce", IFERROR(_xlfn.XLOOKUP(CantoralDB[[#This Row],[Autor]],_xlfn.CHOOSECOLS(_xlfn.ANCHORARRAY(secciones!$A$3),1),_xlfn.CHOOSECOLS(_xlfn.ANCHORARRAY(secciones!$A$3),2)),"nuevas") )))))} -> ain_karem | S12: ="canciones/"&CantoralDB[[#This Row],[Carpeta]]&"/"&IF(CantoralDB[[#This Row],[Autor]]="Taizé en español", SUBSTITUTE(SUBSTITUTE(SUBSTITUTE(SUBSTITUTE(SUBSTITUTE(SUBSTITUTE(SUBSTITUTE(SUBSTITUTE(SUBSTITUTE(SUBSTITUTE(SUBSTITUTE(LOWER(CantoralDB[[#This Row],[Linked]]),"á","a"),"é","e"),"í","i"),"ó","o"),"ú","u")," ","_"),"¿",""),"?",""),"¡",""),"!",""),",","")&".html", SUBSTITUTE(SUBSTITUTE(SUBSTITUTE(SUBSTITUTE(SUBSTITUTE(SUBSTITUTE(SUBSTITUTE(SUBSTITUTE(SUBSTITUTE(SUBSTITUTE(SUBSTITUTE(LOWER(CantoralDB[[#This Row],[Título]]),"á","a"),"é","e"),"í","i"),"ó","o"),"ú","u")," ","_"),"¿",""),"?",""),"¡",""),"!",""),",","")&".html") -> canciones/ain_karem/la_moneda_perdida.html | V12: https://open.spotify.com/intl-es/track/52o5a93tqtQVT8H1mVa3rs?si=237aaccb37f94b68 | W12: =IF(CantoralDB[[#This Row],[Linked]]="X","","<li"& IF(CantoralDB[[#This Row],[Autor]]="-",""," data-author="""&CantoralDB[[#This Row],[Autor]]&"""")& IF(ISBLANK(CantoralDB[[#This Row],[Momento]]),""," data-momento="""&CantoralDB[[#This Row],[Momento]]&"""")& IF(ISBLANK(CantoralDB[[#This Row],[Número]]),""," data-nnew="""&CantoralDB[[#This Row],[Número]]&"""")& IF(ISBLANK(CantoralDB[[#This Row],[Número antiguo]]),""," data-nold="""&CantoralDB[[#This Row],[Número antiguo]]&"""")& IF(ISBLANK(CantoralDB[[#This Row],[Número RCC]]),""," data-nrcc="""&CantoralDB[[#This Row],[Número RCC]]&"""")& "><a href="""&CantoralDB[[#This Row],[Ruta]]&""">"&CantoralDB[[#This Row],[Título]]&"</a></li>") -> <li data-author="Ain Karem"><a href="canciones/ain_karem/la_moneda_perdida.html">La moneda perdida</a></li> | X12: =_xlfn.TEXTBEFORE(_xlfn.TEXTAFTER(CantoralDB[[#This Row],[index.html]],">"),">")&">" -> <a href="canciones/ain_karem/la_moneda_perdida.html">
A13: =ROW(CantoralDB[[#This Row],[Título]])-1 -> 12 | B13: Señor mío y Dios mío | H13: Sol | I13: cej5 | J13: OK | M13: Ain Karem | N13: A todos los pueblos | O13: 12 | P13: 2010 | Q13: {=IF(OR(CantoralDB[[#This Row],[Autor]]="Taizé en español",CantoralDB[[#This Row],[Autor]]="Taizé original",CantoralDB[[#This Row],[Autor]]="Taizé"),"taize", IFERROR(_xlfn.XLOOKUP(CantoralDB[[#This Row],[Autor]],_xlfn.CHOOSECOLS(_xlfn.ANCHORARRAY(secciones!$A$3),1),_xlfn.CHOOSECOLS(_xlfn.ANCHORARRAY(secciones!$A$3),2)), IF(OR(CantoralDB[[#This Row],[Número antiguo]]<>"",CantoralDB[[#This Row],[Número]]<>""),"nsb","nuevas" )))} -> ain_karem | R13: {=IF(CantoralDB[[#This Row],[Autor]]="Taizé original","taize_orig", IF(CantoralDB[[#This Row],[Autor]]="Taizé en español","taize_esp", IF(CantoralDB[[#This Row],[Autor]]="Villancicos","villancicos", IF(OR(CantoralDB[[#This Row],[Número antiguo]]<>"",CantoralDB[[#This Row],[Número]]<>""),"nsb", IF(CantoralDB[[#This Row],[Número RCC]]<>"","rcce", IFERROR(_xlfn.XLOOKUP(CantoralDB[[#This Row],[Autor]],_xlfn.CHOOSECOLS(_xlfn.ANCHORARRAY(secciones!$A$3),1),_xlfn.CHOOSECOLS(_xlfn.ANCHORARRAY(secciones!$A$3),2)),"nuevas") )))))} -> ain_karem | S13: ="canciones/"&CantoralDB[[#This Row],[Carpeta]]&"/"&IF(CantoralDB[[#This Row],[Autor]]="Taizé en español", SUBSTITUTE(SUBSTITUTE(SUBSTITUTE(SUBSTITUTE(SUBSTITUTE(SUBSTITUTE(SUBSTITUTE(SUBSTITUTE(SUBSTITUTE(SUBSTITUTE(SUBSTITUTE(LOWER(CantoralDB[[#This Row],[Linked]]),"á","a"),"é","e"),"í","i"),"ó","o"),"ú","u")," ","_"),"¿",""),"?",""),"¡",""),"!",""),",","")&".html", SUBSTITUTE(SUBSTITUTE(SUBSTITUTE(SUBSTITUTE(SUBSTITUTE(SUBSTITUTE(SUBSTITUTE(SUBSTITUTE(SUBSTITUTE(SUBSTITUTE(SUBSTITUTE(LOWER(CantoralDB[[#This Row],[Título]]),"á","a"),"é","e"),"í","i"),"ó","o"),"ú","u")," ","_"),"¿",""),"?",""),"¡",""),"!",""),",","")&".html") -> canciones/ain_karem/señor_mio_y_dios_mio.html | V13: https://open.spotify.com/intl-es/track/1AiP0ESlQhVMuzxXpsmcyp?si=291920fa66fa4318 | W13: =IF(CantoralDB[[#This Row],[Linked]]="X","","<li"& IF(CantoralDB[[#This Row],[Autor]]="-",""," data-author="""&CantoralDB[[#This Row],[Autor]]&"""")& IF(ISBLANK(CantoralDB[[#This Row],[Momento]]),""," data-momento="""&CantoralDB[[#This Row],[Momento]]&"""")& IF(ISBLANK(CantoralDB[[#This Row],[Número]]),""," data-nnew="""&CantoralDB[[#This Row],[Número]]&"""")& IF(ISBLANK(CantoralDB[[#This Row],[Número antiguo]]),""," data-nold="""&CantoralDB[[#This Row],[Número antiguo]]&"""")& IF(ISBLANK(CantoralDB[[#This Row],[Número RCC]]),""," data-nrcc="""&CantoralDB[[#This Row],[Número RCC]]&"""")& "><a href="""&CantoralDB[[#This Row],[Ruta]]&""">"&CantoralDB[[#This Row],[Título]]&"</a></li>") -> <li data-author="Ain Karem"><a href="canciones/ain_karem/señor_mio_y_dios_mio.html">Señor mío y Dios mío</a></li> | X13: =_xlfn.TEXTBEFORE(_xlfn.TEXTAFTER(CantoralDB[[#This Row],[index.html]],">"),">")&">" -> <a href="canciones/ain_karem/señor_mio_y_dios_mio.html">
A14: =ROW(CantoralDB[[#This Row],[Título]])-1 -> 13 | B14: Dame una palabra | H14: Do | J14: OK | M14: Ain Karem | N14: A todos los pueblos | O14: 13 | P14: 2010 | Q14: {=IF(OR(CantoralDB[[#This Row],[Autor]]="Taizé en español",CantoralDB[[#This Row],[Autor]]="Taizé original",CantoralDB[[#This Row],[Autor]]="Taizé"),"taize", IFERROR(_xlfn.XLOOKUP(CantoralDB[[#This Row],[Autor]],_xlfn.CHOOSECOLS(_xlfn.ANCHORARRAY(secciones!$A$3),1),_xlfn.CHOOSECOLS(_xlfn.ANCHORARRAY(secciones!$A$3),2)), IF(OR(CantoralDB[[#This Row],[Número antiguo]]<>"",CantoralDB[[#This Row],[Número]]<>""),"nsb","nuevas" )))} -> ain_karem | R14: {=IF(CantoralDB[[#This Row],[Autor]]="Taizé original","taize_orig", IF(CantoralDB[[#This Row],[Autor]]="Taizé en español","taize_esp", IF(CantoralDB[[#This Row],[Autor]]="Villancicos","villancicos", IF(OR(CantoralDB[[#This Row],[Número antiguo]]<>"",CantoralDB[[#This Row],[Número]]<>""),"nsb", IF(CantoralDB[[#This Row],[Número RCC]]<>"","rcce", IFERROR(_xlfn.XLOOKUP(CantoralDB[[#This Row],[Autor]],_xlfn.CHOOSECOLS(_xlfn.ANCHORARRAY(secciones!$A$3),1),_xlfn.CHOOSECOLS(_xlfn.ANCHORARRAY(secciones!$A$3),2)),"nuevas") )))))} -> ain_karem | S14: ="canciones/"&CantoralDB[[#This Row],[Carpeta]]&"/"&IF(CantoralDB[[#This Row],[Autor]]="Taizé en español", SUBSTITUTE(SUBSTITUTE(SUBSTITUTE(SUBSTITUTE(SUBSTITUTE(SUBSTITUTE(SUBSTITUTE(SUBSTITUTE(SUBSTITUTE(SUBSTITUTE(SUBSTITUTE(LOWER(CantoralDB[[#This Row],[Linked]]),"á","a"),"é","e"),"í","i"),"ó","o"),"ú","u")," ","_"),"¿",""),"?",""),"¡",""),"!",""),",","")&".html", SUBSTITUTE(SUBSTITUTE(SUBSTITUTE(SUBSTITUTE(SUBSTITUTE(SUBSTITUTE(SUBSTITUTE(SUBSTITUTE(SUBSTITUTE(SUBSTITUTE(SUBSTITUTE(LOWER(CantoralDB[[#This Row],[Título]]),"á","a"),"é","e"),"í","i"),"ó","o"),"ú","u")," ","_"),"¿",""),"?",""),"¡",""),"!",""),",","")&".html") -> canciones/ain_karem/dame_una_palabra.html | V14: https://open.spotify.com/intl-es/track/4804HkPmQkwCH2kF3kwhg6?si=eb80aaa66dfa442b | W14: =IF(CantoralDB[[#This Row],[Linked]]="X","","<li"& IF(CantoralDB[[#This Row],[Autor]]="-",""," data-author="""&CantoralDB[[#This Row],[Autor]]&"""")& IF(ISBLANK(CantoralDB[[#This Row],[Momento]]),""," data-momento="""&CantoralDB[[#This Row],[Momento]]&"""")& IF(ISBLANK(CantoralDB[[#This Row],[Número]]),""," data-nnew="""&CantoralDB[[#This Row],[Número]]&"""")& IF(ISBLANK(CantoralDB[[#This Row],[Número antiguo]]),""," data-nold="""&CantoralDB[[#This Row],[Número antiguo]]&"""")& IF(ISBLANK(CantoralDB[[#This Row],[Número RCC]]),""," data-nrcc="""&CantoralDB[[#This Row],[Número RCC]]&"""")& "><a href="""&CantoralDB[[#This Row],[Ruta]]&""">"&CantoralDB[[#This Row],[Título]]&"</a></li>") -> <li data-author="Ain Karem"><a href="canciones/ain_karem/dame_una_palabra.html">Dame una palabra</a></li> | X14: =_xlfn.TEXTBEFORE(_xlfn.TEXTAFTER(CantoralDB[[#This Row],[index.html]],">"),">")&">" -> <a href="canciones/ain_karem/dame_una_palabra.html">
A15: =ROW(CantoralDB[[#This Row],[Título]])-1 -> 14 | B15: Somos del Señor | H15: Re | I15: cej2 | J15: OK | M15: Ain Karem | N15: A todos los pueblos | O15: 14 | P15: 2010 | Q15: {=IF(OR(CantoralDB[[#This Row],[Autor]]="Taizé en español",CantoralDB[[#This Row],[Autor]]="Taizé original",CantoralDB[[#This Row],[Autor]]="Taizé"),"taize", IFERROR(_xlfn.XLOOKUP(CantoralDB[[#This Row],[Autor]],_xlfn.CHOOSECOLS(_xlfn.ANCHORARRAY(secciones!$A$3),1),_xlfn.CHOOSECOLS(_xlfn.ANCHORARRAY(secciones!$A$3),2)), IF(OR(CantoralDB[[#This Row],[Número antiguo]]<>"",CantoralDB[[#This Row],[Número]]<>""),"nsb","nuevas" )))} -> ain_karem | R15: {=IF(CantoralDB[[#This Row],[Autor]]="Taizé original","taize_orig", IF(CantoralDB[[#This Row],[Autor]]="Taizé en español","taize_esp", IF(CantoralDB[[#This Row],[Autor]]="Villancicos","villancicos", IF(OR(CantoralDB[[#This Row],[Número antiguo]]<>"",CantoralDB[[#This Row],[Número]]<>""),"nsb", IF(CantoralDB[[#This Row],[Número RCC]]<>"","rcce", IFERROR(_xlfn.XLOOKUP(CantoralDB[[#This Row],[Autor]],_xlfn.CHOOSECOLS(_xlfn.ANCHORARRAY(secciones!$A$3),1),_xlfn.CHOOSECOLS(_xlfn.ANCHORARRAY(secciones!$A$3),2)),"nuevas") )))))} -> ain_karem | S15: ="canciones/"&CantoralDB[[#This Row],[Carpeta]]&"/"&IF(CantoralDB[[#This Row],[Autor]]="Taizé en español", SUBSTITUTE(SUBSTITUTE(SUBSTITUTE(SUBSTITUTE(SUBSTITUTE(SUBSTITUTE(SUBSTITUTE(SUBSTITUTE(SUBSTITUTE(SUBSTITUTE(SUBSTITUTE(LOWER(CantoralDB[[#This Row],[Linked]]),"á","a"),"é","e"),"í","i"),"ó","o"),"ú","u")," ","_"),"¿",""),"?",""),"¡",""),"!",""),",","")&".html", SUBSTITUTE(SUBSTITUTE(SUBSTITUTE(SUBSTITUTE(SUBSTITUTE(SUBSTITUTE(SUBSTITUTE(SUBSTITUTE(SUBSTITUTE(SUBSTITUTE(SUBSTITUTE(LOWER(CantoralDB[[#This Row],[Título]]),"á","a"),"é","e"),"í","i"),"ó","o"),"ú","u")," ","_"),"¿",""),"?",""),"¡",""),"!",""),",","")&".html") -> canciones/ain_karem/somos_del_señor.html | V15: https://open.spotify.com/intl-es/track/5Bbi2OqBscgsb9GLPPvIeY?si=e179971c09254637 | W15: =IF(CantoralDB[[#This Row],[Linked]]="X","","<li"& IF(CantoralDB[[#This Row],[Autor]]="-",""," data-author="""&CantoralDB[[#This Row],[Autor]]&"""")& IF(ISBLANK(CantoralDB[[#This Row],[Momento]]),""," data-momento="""&CantoralDB[[#This Row],[Momento]]&"""")& IF(ISBLANK(CantoralDB[[#This Row],[Número]]),""," data-nnew="""&CantoralDB[[#This Row],[Número]]&"""")& IF(ISBLANK(CantoralDB[[#This Row],[Número antiguo]]),""," data-nold="""&CantoralDB[[#This Row],[Número antiguo]]&"""")& IF(ISBLANK(CantoralDB[[#This Row],[Número RCC]]),""," data-nrcc="""&CantoralDB[[#This Row],[Número RCC]]&"""")& "><a href="""&CantoralDB[[#This Row],[Ruta]]&""">"&CantoralDB[[#This Row],[Título]]&"</a></li>") -> <li data-author="Ain Karem"><a href="canciones/ain_karem/somos_del_señor.html">Somos del Señor</a></li> | X15: =_xlfn.TEXTBEFORE(_xlfn.TEXTAFTER(CantoralDB[[#This Row],[index.html]],">"),">")&">" -> <a href="canciones/ain_karem/somos_del_señor.html">
A16: =ROW(CantoralDB[[#This Row],[Título]])-1 -> 15 | B16: Fuertes, humildes y diligentes | H16: La | I16: cej2 | J16: OK | M16: Ain Karem | N16: A todos los pueblos | O16: 15 | P16: 2010 | Q16: {=IF(OR(CantoralDB[[#This Row],[Autor]]="Taizé en español",CantoralDB[[#This Row],[Autor]]="Taizé original",CantoralDB[[#This Row],[Autor]]="Taizé"),"taize", IFERROR(_xlfn.XLOOKUP(CantoralDB[[#This Row],[Autor]],_xlfn.CHOOSECOLS(_xlfn.ANCHORARRAY(secciones!$A$3),1),_xlfn.CHOOSECOLS(_xlfn.ANCHORARRAY(secciones!$A$3),2)), IF(OR(CantoralDB[[#This Row],[Número antiguo]]<>"",CantoralDB[[#This Row],[Número]]<>""),"nsb","nuevas" )))} -> ain_karem | R16: {=IF(CantoralDB[[#This Row],[Autor]]="Taizé original","taize_orig", IF(CantoralDB[[#This Row],[Autor]]="Taizé en español","taize_esp", IF(CantoralDB[[#This Row],[Autor]]="Villancicos","villancicos", IF(OR(CantoralDB[[#This Row],[Número antiguo]]<>"",CantoralDB[[#This Row],[Número]]<>""),"nsb", IF(CantoralDB[[#This Row],[Número RCC]]<>"","rcce", IFERROR(_xlfn.XLOOKUP(CantoralDB[[#This Row],[Autor]],_xlfn.CHOOSECOLS(_xlfn.ANCHORARRAY(secciones!$A$3),1),_xlfn.CHOOSECOLS(_xlfn.ANCHORARRAY(secciones!$A$3),2)),"nuevas") )))))} -> ain_karem | S16: ="canciones/"&CantoralDB[[#This Row],[Carpeta]]&"/"&IF(CantoralDB[[#This Row],[Autor]]="Taizé en español", SUBSTITUTE(SUBSTITUTE(SUBSTITUTE(SUBSTITUTE(SUBSTITUTE(SUBSTITUTE(SUBSTITUTE(SUBSTITUTE(SUBSTITUTE(SUBSTITUTE(SUBSTITUTE(LOWER(CantoralDB[[#This Row],[Linked]]),"á","a"),"é","e"),"í","i"),"ó","o"),"ú","u")," ","_"),"¿",""),"?",""),"¡",""),"!",""),",","")&".html", SUBSTITUTE(SUBSTITUTE(SUBSTITUTE(SUBSTITUTE(SUBSTITUTE(SUBSTITUTE(SUBSTITUTE(SUBSTITUTE(SUBSTITUTE(SUBSTITUTE(SUBSTITUTE(LOWER(CantoralDB[[#This Row],[Título]]),"á","a"),"é","e"),"í","i"),"ó","o"),"ú","u")," ","_"),"¿",""),"?",""),"¡",""),"!",""),",","")&".html") -> canciones/ain_karem/fuertes_humildes_y_diligentes.html | V16: https://open.spotify.com/intl-es/track/2bC2Iiuh9dsOg1VG9bOGVk?si=af7c8eea8e734cf9 | W16: =IF(CantoralDB[[#This Row],[Linked]]="X","","<li"& IF(CantoralDB[[#This Row],[Autor]]="-",""," data-author="""&CantoralDB[[#This Row],[Autor]]&"""")& IF(ISBLANK(CantoralDB[[#This Row],[Momento]]),""," data-momento="""&CantoralDB[[#This Row],[Momento]]&"""")& IF(ISBLANK(CantoralDB[[#This Row],[Número]]),""," data-nnew="""&CantoralDB[[#This Row],[Número]]&"""")& IF(ISBLANK(CantoralDB[[#This Row],[Número antiguo]]),""," data-nold="""&CantoralDB[[#This Row],[Número antiguo]]&"""")& IF(ISBLANK(CantoralDB[[#This Row],[Número RCC]]),""," data-nrcc="""&CantoralDB[[#This Row],[Número RCC]]&"""")& "><a href="""&CantoralDB[[#This Row],[Ruta]]&""">"&CantoralDB[[#This Row],[Título]]&"</a></li>") -> <li data-author="Ain Karem"><a href="canciones/ain_karem/fuertes_humildes_y_diligentes.html">Fuertes, humildes y diligentes</a></li> | X16: =_xlfn.TEXTBEFORE(_xlfn.TEXTAFTER(CantoralDB[[#This Row],[index.html]],">"),">")&">" -> <a href="canciones/ain_karem/fuertes_humildes_y_diligentes.html">
A17: =ROW(CantoralDB[[#This Row],[Título]])-1 -> 16 | B17: Ain Karem | H17: Sol | I17: cej2 | J17: OK | M17: Ain Karem | N17: Alégrate | O17: 1 | P17: 2004 | Q17: {=IF(OR(CantoralDB[[#This Row],[Autor]]="Taizé en español",CantoralDB[[#This Row],[Autor]]="Taizé original",CantoralDB[[#This Row],[Autor]]="Taizé"),"taize", IFERROR(_xlfn.XLOOKUP(CantoralDB[[#This Row],[Autor]],_xlfn.CHOOSECOLS(_xlfn.ANCHORARRAY(secciones!$A$3),1),_xlfn.CHOOSECOLS(_xlfn.ANCHORARRAY(secciones!$A$3),2)), IF(OR(CantoralDB[[#This Row],[Número antiguo]]<>"",CantoralDB[[#This Row],[Número]]<>""),"nsb","nuevas" )))} -> ain_karem | R17: {=IF(CantoralDB[[#This Row],[Autor]]="Taizé original","taize_orig", IF(CantoralDB[[#This Row],[Autor]]="Taizé en español","taize_esp", IF(CantoralDB[[#This Row],[Autor]]="Villancicos","villancicos", IF(OR(CantoralDB[[#This Row],[Número antiguo]]<>"",CantoralDB[[#This Row],[Número]]<>""),"nsb", IF(CantoralDB[[#This Row],[Número RCC]]<>"","rcce", IFERROR(_xlfn.XLOOKUP(CantoralDB[[#This Row],[Autor]],_xlfn.CHOOSECOLS(_xlfn.ANCHORARRAY(secciones!$A$3),1),_xlfn.CHOOSECOLS(_xlfn.ANCHORARRAY(secciones!$A$3),2)),"nuevas") )))))} -> ain_karem | S17: ="canciones/"&CantoralDB[[#This Row],[Carpeta]]&"/"&IF(CantoralDB[[#This Row],[Autor]]="Taizé en español", SUBSTITUTE(SUBSTITUTE(SUBSTITUTE(SUBSTITUTE(SUBSTITUTE(SUBSTITUTE(SUBSTITUTE(SUBSTITUTE(SUBSTITUTE(SUBSTITUTE(SUBSTITUTE(LOWER(CantoralDB[[#This Row],[Linked]]),"á","a"),"é","e"),"í","i"),"ó","o"),"ú","u")," ","_"),"¿",""),"?",""),"¡",""),"!",""),",","")&".html", SUBSTITUTE(SUBSTITUTE(SUBSTITUTE(SUBSTITUTE(SUBSTITUTE(SUBSTITUTE(SUBSTITUTE(SUBSTITUTE(SUBSTITUTE(SUBSTITUTE(SUBSTITUTE(LOWER(CantoralDB[[#This Row],[Título]]),"á","a"),"é","e"),"í","i"),"ó","o"),"ú","u")," ","_"),"¿",""),"?",""),"¡",""),"!",""),",","")&".html") -> canciones/ain_karem/ain_karem.html | V17: https://www.youtube.com/watch?v=ViaYUQp5RHk | W17: =IF(CantoralDB[[#This Row],[Linked]]="X","","<li"& IF(CantoralDB[[#This Row],[Autor]]="-",""," data-author="""&CantoralDB[[#This Row],[Autor]]&"""")& IF(ISBLANK(CantoralDB[[#This Row],[Momento]]),""," data-momento="""&CantoralDB[[#This Row],[Momento]]&"""")& IF(ISBLANK(CantoralDB[[#This Row],[Número]]),""," data-nnew="""&CantoralDB[[#This Row],[Número]]&"""")& IF(ISBLANK(CantoralDB[[#This Row],[Número antiguo]]),""," data-nold="""&CantoralDB[[#This Row],[Número antiguo]]&"""")& IF(ISBLANK(CantoralDB[[#This Row],[Número RCC]]),""," data-nrcc="""&CantoralDB[[#This Row],[Número RCC]]&"""")& "><a href="""&CantoralDB[[#This Row],[Ruta]]&""">"&CantoralDB[[#This Row],[Título]]&"</a></li>") -> <li data-author="Ain Karem"><a href="canciones/ain_karem/ain_karem.html">Ain Karem</a></li> | X17: =_xlfn.TEXTBEFORE(_xlfn.TEXTAFTER(CantoralDB[[#This Row],[index.html]],">"),">")&">" -> <a href="canciones/ain_karem/ain_karem.html">
A18: =ROW(CantoralDB[[#This Row],[Título]])-1 -> 17 | B18: Te basta mi gracia | H18: Do | I18: cej2 | J18: OK | M18: Ain Karem | N18: Alégrate | O18: 2 | P18: 2004 | Q18: {=IF(OR(CantoralDB[[#This Row],[Autor]]="Taizé en español",CantoralDB[[#This Row],[Autor]]="Taizé original",CantoralDB[[#This Row],[Autor]]="Taizé"),"taize", IFERROR(_xlfn.XLOOKUP(CantoralDB[[#This Row],[Autor]],_xlfn.CHOOSECOLS(_xlfn.ANCHORARRAY(secciones!$A$3),1),_xlfn.CHOOSECOLS(_xlfn.ANCHORARRAY(secciones!$A$3),2)), IF(OR(CantoralDB[[#This Row],[Número antiguo]]<>"",CantoralDB[[#This Row],[Número]]<>""),"nsb","nuevas" )))} -> ain_karem | R18: {=IF(CantoralDB[[#This Row],[Autor]]="Taizé original","taize_orig", IF(CantoralDB[[#This Row],[Autor]]="Taizé en español","taize_esp", IF(CantoralDB[[#This Row],[Autor]]="Villancicos","villancicos", IF(OR(CantoralDB[[#This Row],[Número antiguo]]<>"",CantoralDB[[#This Row],[Número]]<>""),"nsb", IF(CantoralDB[[#This Row],[Número RCC]]<>"","rcce", IFERROR(_xlfn.XLOOKUP(CantoralDB[[#This Row],[Autor]],_xlfn.CHOOSECOLS(_xlfn.ANCHORARRAY(secciones!$A$3),1),_xlfn.CHOOSECOLS(_xlfn.ANCHORARRAY(secciones!$A$3),2)),"nuevas") )))))} -> ain_karem | S18: ="canciones/"&CantoralDB[[#This Row],[Carpeta]]&"/"&IF(CantoralDB[[#This Row],[Autor]]="Taizé en español", SUBSTITUTE(SUBSTITUTE(SUBSTITUTE(SUBSTITUTE(SUBSTITUTE(SUBSTITUTE(SUBSTITUTE(SUBSTITUTE(SUBSTITUTE(SUBSTITUTE(SUBSTITUTE(LOWER(CantoralDB[[#This Row],[Linked]]),"á","a"),"é","e"),"í","i"),"ó","o"),"ú","u")," ","_"),"¿",""),"?",""),"¡",""),"!",""),",","")&".html", SUBSTITUTE(SUBSTITUTE(SUBSTITUTE(SUBSTITUTE(SUBSTITUTE(SUBSTITUTE(SUBSTITUTE(SUBSTITUTE(SUBSTITUTE(SUBSTITUTE(SUBSTITUTE(LOWER(CantoralDB[[#This Row],[Título]]),"á","a"),"é","e"),"í","i"),"ó","o"),"ú","u")," ","_"),"¿",""),"?",""),"¡",""),"!",""),",","")&".html") -> canciones/ain_karem/te_basta_mi_gracia.html | V18: https://www.youtube.com/watch?v=-VdcljDSRgU | W18: =IF(CantoralDB[[#This Row],[Linked]]="X","","<li"& IF(CantoralDB[[#This Row],[Autor]]="-",""," data-author="""&CantoralDB[[#This Row],[Autor]]&"""")& IF(ISBLANK(CantoralDB[[#This Row],[Momento]]),""," data-momento="""&CantoralDB[[#This Row],[Momento]]&"""")& IF(ISBLANK(CantoralDB[[#This Row],[Número]]),""," data-nnew="""&CantoralDB[[#This Row],[Número]]&"""")& IF(ISBLANK(CantoralDB[[#This Row],[Número antiguo]]),""," data-nold="""&CantoralDB[[#This Row],[Número antiguo]]&"""")& IF(ISBLANK(CantoralDB[[#This Row],[Número RCC]]),""," data-nrcc="""&CantoralDB[[#This Row],[Número RCC]]&"""")& "><a href="""&CantoralDB[[#This Row],[Ruta]]&""">"&CantoralDB[[#This Row],[Título]]&"</a></li>") -> <li data-author="Ain Karem"><a href="canciones/ain_karem/te_basta_mi_gracia.html">Te basta mi gracia</a></li> | X18: =_xlfn.TEXTBEFORE(_xlfn.TEXTAFTER(CantoralDB[[#This Row],[index.html]],">"),">")&">" -> <a href="canciones/ain_karem/te_basta_mi_gracia.html">
A19: =ROW(CantoralDB[[#This Row],[Título]])-1 -> 18 | B19: Poneos en pie | H19: Do | I19: cej3 | J19: OK | M19: Ain Karem | N19: Alégrate | O19: 3 | P19: 2004 | Q19: {=IF(OR(CantoralDB[[#This Row],[Autor]]="Taizé en español",CantoralDB[[#This Row],[Autor]]="Taizé original",CantoralDB[[#This Row],[Autor]]="Taizé"),"taize", IFERROR(_xlfn.XLOOKUP(CantoralDB[[#This Row],[Autor]],_xlfn.CHOOSECOLS(_xlfn.ANCHORARRAY(secciones!$A$3),1),_xlfn.CHOOSECOLS(_xlfn.ANCHORARRAY(secciones!$A$3),2)), IF(OR(CantoralDB[[#This Row],[Número antiguo]]<>"",CantoralDB[[#This Row],[Número]]<>""),"nsb","nuevas" )))} -> ain_karem | R19: {=IF(CantoralDB[[#This Row],[Autor]]="Taizé original","taize_orig", IF(CantoralDB[[#This Row],[Autor]]="Taizé en español","taize_esp", IF(CantoralDB[[#This Row],[Autor]]="Villancicos","villancicos", IF(OR(CantoralDB[[#This Row],[Número antiguo]]<>"",CantoralDB[[#This Row],[Número]]<>""),"nsb", IF(CantoralDB[[#This Row],[Número RCC]]<>"","rcce", IFERROR(_xlfn.XLOOKUP(CantoralDB[[#This Row],[Autor]],_xlfn.CHOOSECOLS(_xlfn.ANCHORARRAY(secciones!$A$3),1),_xlfn.CHOOSECOLS(_xlfn.ANCHORARRAY(secciones!$A$3),2)),"nuevas") )))))} -> ain_karem | S19: ="canciones/"&CantoralDB[[#This Row],[Carpeta]]&"/"&IF(CantoralDB[[#This Row],[Autor]]="Taizé en español", SUBSTITUTE(SUBSTITUTE(SUBSTITUTE(SUBSTITUTE(SUBSTITUTE(SUBSTITUTE(SUBSTITUTE(SUBSTITUTE(SUBSTITUTE(SUBSTITUTE(SUBSTITUTE(LOWER(CantoralDB[[#This Row],[Linked]]),"á","a"),"é","e"),"í","i"),"ó","o"),"ú","u")," ","_"),"¿",""),"?",""),"¡",""),"!",""),",","")&".html", SUBSTITUTE(SUBSTITUTE(SUBSTITUTE(SUBSTITUTE(SUBSTITUTE(SUBSTITUTE(SUBSTITUTE(SUBSTITUTE(SUBSTITUTE(SUBSTITUTE(SUBSTITUTE(LOWER(CantoralDB[[#This Row],[Título]]),"á","a"),"é","e"),"í","i"),"ó","o"),"ú","u")," ","_"),"¿",""),"?",""),"¡",""),"!",""),",","")&".html") -> canciones/ain_karem/poneos_en_pie.html | V19: https://www.youtube.com/watch?v=oSPCNIvKDsk | W19: =IF(CantoralDB[[#This Row],[Linked]]="X","","<li"& IF(CantoralDB[[#This Row],[Autor]]="-",""," data-author="""&CantoralDB[[#This Row],[Autor]]&"""")& IF(ISBLANK(CantoralDB[[#This Row],[Momento]]),""," data-momento="""&CantoralDB[[#This Row],[Momento]]&"""")& IF(ISBLANK(CantoralDB[[#This Row],[Número]]),""," data-nnew="""&CantoralDB[[#This Row],[Número]]&"""")& IF(ISBLANK(CantoralDB[[#This Row],[Número antiguo]]),""," data-nold="""&CantoralDB[[#This Row],[Número antiguo]]&"""")& IF(ISBLANK(CantoralDB[[#This Row],[Número RCC]]),""," data-nrcc="""&CantoralDB[[#This Row],[Número RCC]]&"""")& "><a href="""&CantoralDB[[#This Row],[Ruta]]&""">"&CantoralDB[[#This Row],[Título]]&"</a></li>") -> <li data-author="Ain Karem"><a href="canciones/ain_karem/poneos_en_pie.html">Poneos en pie</a></li> | X19: =_xlfn.TEXTBEFORE(_xlfn.TEXTAFTER(CantoralDB[[#This Row],[index.html]],">"),">")&">" -> <a href="canciones/ain_karem/poneos_en_pie.html">
